<?xml version="1.0"?>
<robot xmlns:xacro="http://www.ros.org/wiki/xacro" name="gripper">
    <xacro:macro name="gripper" params="parent_link *origin_block">
        <link name="gripper_base">
            <visual>
                <origin xyz="0 0 0" rpy="0 0 0" />
                <geometry>
                    <mesh filename="package://visiona_bridge/meshes/gripper_joint.stl"
                        scale="0.001 0.001 0.001" />
                </geometry>
            </visual>
            <!-- <collision>
                <origin xyz="0 0 0" rpy="0 0 0" />
                <geometry>
                    <mesh filename="package://visiona_bridge/meshes/gripper_joint.stl"
                        scale="0.001 0.001 0.001" />
                </geometry>
            </collision> -->
            <inertial>
                <mass value="0.1" />
                <inertia ixx="0.01" ixy="0" ixz="0" iyy="0.01" iyz="0" izz="0.01" />
            </inertial>
        </link>

        <joint name="${parent_link}_to_gripper_base_joint" type="revolute">
            <parent link="${parent_link}" />
            <child link="gripper_base" />
            <xacro:insert_block name="origin_block" />

            <axis xyz="0 1 0.0" />
            <limit lower="-3.0" upper="3.0" effort="100.0" velocity="10.0" />
            <!-- <dynamics damping="10" friction="10" /> -->

        </joint>

        <link name="left_finger_link">
            <visual>
                <origin xyz="0 0 0" rpy="0 0 0" />
                <geometry>
                    <mesh filename="package://visiona_bridge/meshes/gripper_left_finger.stl"
                        scale="0.001 0.001 0.001" />
                </geometry>
            </visual>
            <!-- <collision>
                <origin xyz="0 0 0" rpy="0 0 0" />
                <geometry>
                    <mesh filename="package://visiona_bridge/meshes/gripper_left_finger.stl"
                        scale="0.001 0.001 0.001" />
                </geometry>
            </collision> -->
            <inertial>
                <mass value="0.1" />
                <inertia ixx="0.01" ixy="0" ixz="0" iyy="0.01" iyz="0" izz="0.01" />
            </inertial>
        </link>

        <link name="right_finger_link">
            <visual>

                <origin xyz="0 0 0" rpy="0 0 0" />
                <geometry>
                    <mesh filename="package://visiona_bridge/meshes/gripper_right_finger.stl"
                        scale="0.001 0.001 0.001" />
                </geometry>
            </visual>
            <!-- <collision>
                <origin xyz="0 0 0" rpy="0 0 0" />
                <geometry>
                    <mesh filename="package://visiona_bridge/meshes/gripper_right_finger.stl"
                        scale="0.001 0.001 0.001" />
                </geometry>
            </collision> -->
            <inertial>
                <mass value="0.1" />
                <inertia ixx="0.01" ixy="0" ixz="0" iyy="0.01" iyz="0" izz="0.01" />
            </inertial>
        </link>

        <joint name="left_finger_joint" type="revolute">
            <parent link="gripper_base" />
            <child link="left_finger_link" />
            <origin xyz="0.0 0.0 0" rpy="0 0 0" />
            <axis xyz="0 0 1" />
            <limit lower="-1.0" upper="1" effort="100.0" velocity="10.0" />
            <!-- <dynamics damping="10" friction="10" /> -->

        </joint>

        <joint name="right_finger_joint" type="revolute">
            <parent link="gripper_base" />
            <child link="right_finger_link" />
            <origin xyz="0 0 0" rpy="0 0 0" />
            <axis xyz="0 0 1" />
            <limit lower="-1.0" upper="1" effort="100.0" velocity="10.0" />
            <!-- <dynamics damping="10" friction="10" /> -->

            <mimic joint="left_finger_joint" multiplier="-1" offset="0.0" />
        </joint>

    </xacro:macro>

</robot>