<?xml version="1.0"?>
<robot name="my_robot_arm" xmlns:xacro="http://www.ros.org/wiki/xacro">

  <xacro:arg name="controller_config_path" default=""/>
  <xacro:property name="package_path" value="$(find my_robot_description)" />

  <link name="world" />
  <link name="base_footprint" />

  <joint name="base_footprint_joint" type="fixed">
    <parent link="world"/>
    <child link="base_footprint"/>
    <origin xyz="0 0 0.01" rpy="0 0 0"/>
  </joint>

  <link name="base">
    <visual>
      <origin rpy="0 0 0" xyz="0 0 0"/>
      <geometry>
        <mesh filename="${package_path}/meshes/base.stl" scale="0.001 0.001 0.001"/>
      </geometry>
    </visual>
    <collision>
      <origin rpy="0 0 0" xyz="0 0 0"/>
      <geometry>
        <mesh filename="${package_path}/meshes/base.stl" scale="0.001 0.001 0.001"/>
      </geometry>
    </collision>
    <inertial>
      <mass value="2.5"/>
      <inertia ixx="0.01" ixy="0" ixz="0" iyy="0.01" iyz="0" izz="0.01"/>
    </inertial>
  </link>

  <joint name="base_joint" type="fixed">
    <parent link="base_footprint"/>
    <child link="base"/>
    <origin xyz="0 0 0" rpy="0 0 0"/>
  </joint>

  <link name="base_link">
    <visual>
      <origin rpy="0 0 0" xyz="0 0 0"/>
      <geometry>
        <mesh filename="${package_path}/meshes/base_link.stl" scale="0.001 0.001 0.001"/>
      </geometry>
    </visual>
    <collision>
      <origin rpy="0 0 0" xyz="0 0 0"/>
      <geometry>
        <mesh filename="${package_path}/meshes/base_link.stl" scale="0.001 0.001 0.001"/>
      </geometry>
    </collision>
    <inertial>
      <mass value="1.5"/>
      <inertia ixx="0.01" ixy="0" ixz="0" iyy="0.01" iyz="0" izz="0.01"/>
    </inertial>
  </link>
  <link name="link_1_shoulder">
    <visual>
      <origin rpy="0 0 0" xyz="0 0 0"/>
      <geometry>
        <mesh filename="${package_path}/meshes/link_1_shoulder.stl" scale="0.001 0.001 0.001"/>
      </geometry>
    </visual>
    <collision>
      <origin rpy="0 0 0" xyz="0 0 0"/>
      <geometry>
        <mesh filename="${package_path}/meshes/link_1_shoulder.stl" scale="0.001 0.001 0.001"/>
      </geometry>
    </collision>
    <inertial>
      <mass value="1.2"/>
      <inertia ixx="0.01" ixy="0" ixz="0" iyy="0.01" iyz="0" izz="0.01"/>
    </inertial>
  </link>
  <link name="link_2_elbow">
    <visual>
      <origin rpy="0 0 0" xyz="0 0 0"/>
      <geometry>
        <mesh filename="${package_path}/meshes/link_2_elbow.stl" scale="0.001 0.001 0.001"/>
      </geometry>
    </visual>
    <collision>
      <origin rpy="0 0 0" xyz="0 0 0"/>
      <geometry>
        <mesh filename="${package_path}/meshes/link_2_elbow.stl" scale="0.001 0.001 0.001"/>
      </geometry>
    </collision>
    <inertial>
      <mass value="1.0"/>
      <inertia ixx="0.01" ixy="0" ixz="0" iyy="0.01" iyz="0" izz="0.01"/>
    </inertial>
  </link>
  <link name="link_3_wrist">
    <visual>
      <origin rpy="0 0 0" xyz="0 0 0"/>
      <geometry>
        <mesh filename="${package_path}/meshes/link_3_wrist.stl" scale="0.001 0.001 0.001"/>
      </geometry>
    </visual>
    <collision>
      <origin rpy="0 0 0" xyz="0 0 0"/>
      <geometry>
        <mesh filename="${package_path}/meshes/link_3_wrist.stl" scale="0.001 0.001 0.001"/>
      </geometry>
    </collision>
    <inertial>
      <mass value="0.8"/>
      <inertia ixx="0.001" ixy="0" ixz="0" iyy="0.001" iyz="0" izz="0.001"/>
    </inertial>
  </link>
  <link name="link_4_wrist">
    <visual>
      <origin rpy="0 0 0" xyz="0 0 0"/>
      <geometry>
        <mesh filename="${package_path}/meshes/link_4_wrist.stl" scale="0.001 0.001 0.001"/>
      </geometry>
    </visual>
    <collision>
      <origin rpy="0 0 0" xyz="0 0 0"/>
      <geometry>
        <mesh filename="${package_path}/meshes/link_4_wrist.stl" scale="0.001 0.001 0.001"/>
      </geometry>
    </collision>
    <inertial>
      <mass value="0.5"/>
      <inertia ixx="0.001" ixy="0" ixz="0" iyy="0.001" iyz="0" izz="0.001"/>
    </inertial>
  </link>
 

  <joint name="joint1" type="revolute">
    <parent link="base"/>
    <child link="base_link"/>
    <origin rpy="0 0 0" xyz="0 0 0.076"/>
    <axis xyz="0 0 1"/>
    <limit effort="100" lower="-3.14" upper="3.14" velocity="1.0"/>
  </joint>
  <joint name="joint2" type="revolute">
    <parent link="base_link"/>
    <child link="link_1_shoulder"/>
    <origin rpy="0 0 0" xyz="0.0145 0 0.07"/>
    <axis xyz="1 0 0"/>
    <limit effort="100" lower="-1.5" upper="1.5" velocity="1.0"/>
  </joint>
  <joint name="joint3" type="revolute">
    <parent link="link_1_shoulder"/>
    <child link="link_2_elbow"/>
    <origin rpy="0 0 0" xyz="-0.033 0 0.18"/>
    <axis xyz="1 0 0"/>
    <limit effort="100" lower="-1.5" upper="1.5" velocity="1.0"/>
  </joint>
  <joint name="joint4" type="revolute">
    <parent link="link_2_elbow"/>
    <child link="link_3_wrist"/>
    <origin rpy="-1.5707963267948966 0 0" xyz="0.029 0 0.117"/>
    <axis xyz="1 0 0"/>
    <limit effort="100" lower="-3.14" upper="3.14" velocity="1.0"/>
  </joint>
  <joint name="joint5" type="revolute">
    <parent link="link_3_wrist"/>
    <child link="link_4_wrist"/>
    <origin rpy="3.141592653589793 0 0" xyz="-0.018 0 -0.12"/>
    <axis xyz="0 1 0"/>
    <limit effort="100" lower="-3.14" upper="3.14" velocity="1.0"/>
  </joint>

  <ros2_control name="GazeboSystem" type="system">
    <hardware>
      <plugin>gazebo_ros2_control/GazeboSystem</plugin>
    </hardware>
    <joint name="joint1">
      <command_interface name="position"/>
      <state_interface name="position"/>
      <state_interface name="velocity"/>
    </joint>
    <joint name="joint2">
      <command_interface name="position"/>
      <state_interface name="position"/>
      <state_interface name="velocity"/>
    </joint>
    <joint name="joint3">
      <command_interface name="position"/>
      <state_interface name="position"/>
      <state_interface name="velocity"/>
    </joint>
    <joint name="joint4">
      <command_interface name="position"/>
      <state_interface name="position"/>
      <state_interface name="velocity"/>
    </joint>
    <joint name="joint5">
      <command_interface name="position"/>
      <state_interface name="position"/>
      <state_interface name="velocity"/>
    </joint>
  </ros2_control>

   <gazebo>
    <plugin filename="libgazebo_ros2_control.so" name="gazebo_ros2_control">
      <parameters>$(arg controller_config_path)</parameters>
    </plugin>
  </gazebo>

</robot>